# [\#26 Issue](https://github.com/mattduck/gh2md/issues/26) `closed`: Can't fetch issues from public repo

#### <img src="https://avatars.githubusercontent.com/u/581023?u=2fa91b813ce6c1161a2337869a3ee0b3cc7ab755&v=4" width="50">[kirillt](https://github.com/kirillt) opened issue at [2022-03-29 07:40](https://github.com/mattduck/gh2md/issues/26):

```
[kirill@lenovo tmp]$ gh2md ethereum/EIPs --no-prs --multiple-files eips/
[2022-03-29 10:39:54,161] [INFO] Looking for token in file: /home/kirill/.config/gh2md/token
[2022-03-29 10:39:54,161] [INFO] Looking for token in file: /home/kirill/.github-token
[2022-03-29 10:39:54,161] [WARNING] No token found. Access to private repositories will fail
[2022-03-29 10:39:54,161] [INFO] Initiating fetch for repo: ethereum/EIPs
[2022-03-29 10:39:54,162] [WARNING] Exception response from request attempt 1
Traceback (most recent call last):
  File "/usr/local/lib/python3.8/site-packages/gh2md/gh2md.py", line 364, in _post
    resp = self._request_session().post(
  File "/usr/local/lib/python3.8/site-packages/gh2md/gh2md.py", line 350, in _request_session
    self._session.headers.update({"Authorization": "token " + self.token})
TypeError: can only concatenate str (not "NoneType") to str
[2022-03-29 10:39:57,592] [WARNING] Exception response from request attempt 2
Traceback (most recent call last):
  File "/usr/local/lib/python3.8/site-packages/gh2md/gh2md.py", line 367, in _post
    resp.raise_for_status()
  File "/usr/local/lib/python3.8/site-packages/requests/models.py", line 960, in raise_for_status
    raise HTTPError(http_error_msg, response=self)
requests.exceptions.HTTPError: 401 Client Error: Unauthorized for url: https://api.github.com/graphql
[2022-03-29 10:40:00,595] [ERROR] Request failed multiple retries, returning empty data
[2022-03-29 10:40:00,595] [ERROR] Repository data missing in response, can't proceed
Traceback (most recent call last):
  File "/usr/local/bin/gh2md", line 8, in <module>
    sys.exit(main())
  File "/usr/local/lib/python3.8/site-packages/gh2md/gh2md.py", line 791, in main
    repo = gh.fetch_and_decode_repository(
  File "/usr/local/lib/python3.8/site-packages/gh2md/gh2md.py", line 566, in fetch_and_decode_repository
    repo_data = response["data"]["repository"]
KeyError: 'data'
```

#### <img src="https://avatars.githubusercontent.com/u/1917293?v=4" width="50">[ronna](https://github.com/ronna) commented at [2022-06-22 15:03](https://github.com/mattduck/gh2md/issues/26#issuecomment-1163225851):

Hi @kirillt 

You need to set the Github token even if you just want to pull public repos.

#### <img src="https://avatars.githubusercontent.com/u/1607892?u=196bf09c14472eee8dccaaecbef3c16974c8e69f&v=4" width="50">[mattduck](https://github.com/mattduck) commented at [2022-06-29 20:18](https://github.com/mattduck/gh2md/issues/26#issuecomment-1170454551):

Thanks for raising - I can update the docs + error handling here to make this more explicit

#### <img src="https://avatars.githubusercontent.com/u/1607892?u=196bf09c14472eee8dccaaecbef3c16974c8e69f&v=4" width="50">[mattduck](https://github.com/mattduck) commented at [2022-07-17 10:00](https://github.com/mattduck/gh2md/issues/26#issuecomment-1186465168):

Exiting and error output has been updated in 2.3.0, hopefully this is more explicit for everyone in future:

```
$ gh2md mattduck/gh2md export.md
[2022-07-17 10:58:26,888] [INFO] Looking for token in envvar GITHUB_ACCESS_TOKEN
[2022-07-17 10:58:26,888] [INFO] Looking for token in file: /f/users/matt/.config/gh2md/token
[2022-07-17 10:58:26,889] [INFO] Looking for token in file: /f/users/matt/.github-token
No Github access token found, exiting. Use gh2md --help so see options for providing a token.
```


-------------------------------------------------------------------------------



[Export of Github issue for [mattduck/gh2md](https://github.com/mattduck/gh2md). Generated on 2022.08.23 at 12:38:24.]
